2023-11-30 23:54:53,465 - logger - INFO - ------
2023-11-30 23:54:53,465 - logger - INFO - retrieve station status
2023-11-30 23:54:54,042 - logger - INFO - request status: Successful
2023-11-30 23:54:54,042 - logger - ERROR - Unexpected failure
Traceback (most recent call last):
  File "/home/runner/work/velibs-data-dump/velibs-data-dump/utils.py", line 20, in dump_data_from_api
    with open(output_path, 'w') as output:
FileNotFoundError: [Errno 2] No such file or directory: './history/station_status__2023-11-30-23-54.json'
2023-11-30 23:54:54,043 - logger - INFO - retrieve station information
2023-11-30 23:54:54,839 - logger - INFO - request status: Successful
2023-11-30 23:54:54,842 - logger - ERROR - Unexpected failure
Traceback (most recent call last):
  File "/home/runner/work/velibs-data-dump/velibs-data-dump/utils.py", line 20, in dump_data_from_api
    with open(output_path, 'w') as output:
FileNotFoundError: [Errno 2] No such file or directory: './history/station_information__2023-11-30-23-54.json'
2023-11-30 23:54:54,843 - logger - INFO - ------
